<?xml version="1.0" encoding="UTF-8"?>
<robot name="widowx" xmlns:xacro="http://ros.org/wiki/xacro">
 
	<material name="yellow">
		<color rgba="0.15 0.15 0.15 1.0"/>
	</material>

	<material name="white">
		<color rgba="0.86 0.85 0.81 1.0"/>
	</material>

	<material name="black">
		<color rgba="0.15 0.15 0.15 1.0"/>
	</material>

	<material name="grey">
		<color rgba="0.34 0.35 0.36 1.0"/>
	</material>


	<material name="greyish">
		<color rgba="0.75 0.75 0.75 1.0"/>
	</material>
	
	
  
  <link name="arm_base_link">
     <visual>
        <origin xyz="0 0 0" rpy="0 0 0" />
        <geometry>
           <mesh filename="meshes/base_link.stl"/>
        </geometry>
        <material name="black"/>
   </visual>
     <collision>
        <origin xyz="0 0 0" rpy="0 0 0" />
        <geometry>
           <mesh filename="meshes/base_link.stl"/>
        </geometry>
     </collision>
     <inertial>
        <origin xyz="0 0 0" rpy="0 0 0" />
        <mass value="13" />
        <inertia ixx="1.0" ixy="0.0" ixz="0.0" iyy="1.0" iyz="0.0" izz="1.0" />
     </inertial>
  </link>
  <link name="shoulder_link">
     <visual>
        <origin xyz="0 0 0" rpy="0 0 0" />
        <geometry>
           <mesh filename="meshes/shoulder_link.stl" />
        </geometry>
        <material name="yellow"/>
     </visual>
     <collision>
        <origin xyz="0 0 0" rpy="0 0 0" />
        <geometry>
           <mesh filename="meshes/shoulder_link.stl"/>
        </geometry>
     </collision>
     <inertial>
        <origin xyz="0 0 0" rpy="0 0 0" />
        <mass value=".1" />
        <inertia ixx="1.0" ixy="0.0" ixz="0.0" iyy="1.0" iyz="0.0" izz="1.0" />
     </inertial>
  </link>
  <link name="biceps_link">
     <visual>
	      <origin xyz="0.04825 0 0.140" rpy="0 0 0" />
        <!--origin xyz="0 0 0" rpy="0 0 0" /-->
        <geometry>
           <mesh filename="meshes/biceps_link.stl" />
        </geometry>
        <material name="greyish"/>
     </visual>
     <collision>
        <origin xyz="0.04825 0 0.140" rpy="0 0 0" />
        <geometry>
           <mesh filename="meshes/biceps_link.stl" />
        </geometry>
     </collision>
     <inertial>
        <origin xyz="0 0 0" rpy="0 0 0" />
        <mass value=".1" />
        <inertia ixx="1.0" ixy="0.0" ixz="0.0" iyy="1.0" iyz="0.0" izz="1.0" />
     </inertial>
  </link>
 
  <joint name="joint_1" type="revolute">
     <origin xyz="0 0 0.125" rpy="0 0 1.7" />
     <parent link="arm_base_link" />
     <child link="shoulder_link" />
     <axis xyz="0 0 1" />
     <limit lower="-2.617" upper="2.617" effort="0" velocity="0.785" />
  </joint>
  <joint name="joint_2" type="revolute">
     <!--origin xyz="0.04825 0 0.14203" rpy="0 0 0" /-->
     <origin xyz="0 0 0" rpy="0 1.7 0" />
     <parent link="shoulder_link" />
     <child link="biceps_link" />
     <axis xyz="0 1 0" />
     <limit lower="-1.571" upper="1.571" effort="0" velocity="1.571" />
  </joint>

</robot>
